Workbook
Name MLEDGER: 'MAIN-LEXUS-FAISAL'!$A$59:$F$100

Sheet MAIN-LEXUS-FAISAL
A1: STAR REGENCY LIMOUSINE TRANSPORTATION VIA LUXURY CARS
A2: Hamed Center Building |Ground Floor | Electra St | Abu Dhabi, U.A.E
C4: CUSTOMER INFORMATION
C5: CUSTOMER NAME | D5: MUHAMMAD FAISAL | F5: *
C6: CONTACT NO | D6: +971 56 736 8995 | F6: *
C7: EID NO | D7: 784-1994-2162004-2 | F7: *
G8: EMI BREAKDOWN SCHEDULE
C9: VEHICLE INFORMATION
C10: VEHICLE NAME | D10: LEXUS ES300H | F10: * | G10: EMINO | H10: MONTH | I10: AMOUNT | J10: BALANCE AMT
C11: CHASIS NO | D11: JTHB21B16S2265896 | F11: * | G11: 1 | H11: =D58 -> 45870 | I11: =$D$25 -> 4706 | J11: =D23-I11 -> 164710
C12: ENGINE NO | D12: 3E71377 | F12: * | G12: 2 | H12: =EDATE(H11,1) -> 45901 | I12: =$D$25 -> 4706 | J12: =D$23-SUM(I$11:I12) -> 160004
C13: PURCH DT | D13: 45767 | F13: * | G13: 3 | H13: =EDATE(H12,1) -> 45931 | I13: =$D$25 -> 4706 | J13: =D$23-SUM(I$11:I13) -> 155298
C14: MAKE / COLOR | D14: WHITE / PEARLS | F14: * | G14: 4 | H14: =EDATE(H13,1) -> 45962 | I14: =$D$25 -> 4706 | J14: =D$23-SUM(I$11:I14) -> 150592
G15: 5 | H15: =EDATE(H14,1) -> 45992 | I15: =$D$25 -> 4706 | J15: =D$23-SUM(I$11:I15) -> 145886
C16: DOWN PAYMENT / EMI | G16: 6 | H16: =EDATE(H15,1) -> 46023 | I16: =$D$25 -> 4706 | J16: =D$23-SUM(I$11:I16) -> 141180
C17: VEHICLE COST (AED) | D17: 199000 | E17: * | G17: 7 | H17: =EDATE(H16,1) -> 46054 | I17: =$D$25 -> 4706 | J17: =D$23-SUM(I$11:I17) -> 136474
C18: DOWN PAYMENT(%) | D18: 25 | E18: * | G18: 8 | H18: =EDATE(H17,1) -> 46082 | I18: =$D$25 -> 4706 | J18: =D$23-SUM(I$11:I18) -> 131768
C19: DOWN PAYMENT AMT | D19: =D17*D18/100 -> 49750 | G19: 9 | H19: =EDATE(H18,1) -> 46113 | I19: =$D$25 -> 4706 | J19: =D$23-SUM(I$11:I19) -> 127062
C20: BALANCE A/DP AMT | D20: =D17-D19 -> 149250 | G20: 10 | H20: =EDATE(H19,1) -> 46143 | I20: =$D$25 -> 4706 | J20: =D$23-SUM(I$11:I20) -> 122356
C21: INTEREST RATE | D21: 0.045038526 | E21: / Year | G21: 11 | H21: =EDATE(H20,1) -> 46174 | I21: =$D$25 -> 4706 | J21: =D$23-SUM(I$11:I21) -> 117650
C22: INTEREST PAYABLE | D22: =D20*D21*3 -> 20166 | G22: 12 | H22: =EDATE(H21,1) -> 46204 | I22: =$D$25 -> 4706 | J22: =D$23-SUM(I$11:I22) -> 112944
C23: TOTAL PAYABLE FOR EMI | D23: =D20+D22 -> 169416 | G23: 13 | H23: =EDATE(H22,1) -> 46235 | I23: =$D$25 -> 4706 | J23: =D$23-SUM(I$11:I23) -> 108238
C24: NO OF EMI | D24: 36 | E24: 3 Years | G24: 14 | H24: =EDATE(H23,1) -> 46266 | I24: =$D$25 -> 4706 | J24: =D$23-SUM(I$11:I24) -> 103532
C25: EMI AMT | D25: =D23/D24 -> 4706 | E25: Monthly Installment | G25: 15 | H25: =EDATE(H24,1) -> 46296 | I25: =$D$25 -> 4706 | J25: =D$23-SUM(I$11:I25) -> 98826
G26: 16 | H26: =EDATE(H25,1) -> 46327 | I26: =$D$25 -> 4706 | J26: =D$23-SUM(I$11:I26) -> 94120
G27: 17 | H27: =EDATE(H26,1) -> 46357 | I27: =$D$25 -> 4706 | J27: =D$23-SUM(I$11:I27) -> 89414
C28: INITIAL EXPENSES | G28: 18 | H28: =EDATE(H27,1) -> 46388 | I28: =$D$25 -> 4706 | J28: =D$23-SUM(I$11:I28) -> 84708
C29: PARTICULARS | D29: YEAR-1 | E29: YEAR-2 | F29: YEAR-3 | G29: 19 | H29: =EDATE(H28,1) -> 46419 | I29: =$D$25 -> 4706 | J29: =D$23-SUM(I$11:I29) -> 80002
C30: BANK PROCESSING FEE | D30: 1890 | G30: 20 | H30: =EDATE(H29,1) -> 46447 | I30: =$D$25 -> 4706 | J30: =D$23-SUM(I$11:I30) -> 75296
C31: TRANS PERMIT 1 YR | D31: 7500 | E31: 7500 | F31: 7500 | G31: 21 | H31: =EDATE(H30,1) -> 46478 | I31: =$D$25 -> 4706 | J31: =D$23-SUM(I$11:I31) -> 70590
C32: TRANS PERMIT CARD 2 YRS | D32: 550 | F32: 400 | G32: 22 | H32: =EDATE(H31,1) -> 46508 | I32: =$D$25 -> 4706 | J32: =D$23-SUM(I$11:I32) -> 65884
C33: GPRS TRACKING FEE | D33: 500 | E33: 500 | F33: 500 | G33: 23 | H33: =EDATE(H32,1) -> 46539 | I33: =$D$25 -> 4706 | J33: =D$23-SUM(I$11:I33) -> 61178
C34: FLEET INSURANCE FEE | D34: 7500 | E34: 6500 | F34: 5500 | G34: 24 | H34: =EDATE(H33,1) -> 46569 | I34: =$D$25 -> 4706 | J34: =D$23-SUM(I$11:I34) -> 56472
C35: VEHICLE REGISTRATION FEE | D35: 500 | E35: 370 | F35: 370 | G35: 25 | H35: =EDATE(H34,1) -> 46600 | I35: =$D$25 -> 4706 | J35: =D$23-SUM(I$11:I35) -> 51766
C36: DARB NEW A/C ACTIVATION FEE | D36: 50 | G36: 26 | H36: =EDATE(H35,1) -> 46631 | I36: =$D$25 -> 4706 | J36: =D$23-SUM(I$11:I36) -> 47060
C37: KAFALATH EXPENSE | D37: 7500 | E37: 8000 | F37: 8000 | G37: 27 | H37: =EDATE(H36,1) -> 46661 | I37: =$D$25 -> 4706 | J37: =D$23-SUM(I$11:I37) -> 42354
C38: VISA EXPENSES | D38: 7500 | F38: 7500 | G38: 28 | H38: =EDATE(H37,1) -> 46692 | I38: =$D$25 -> 4706 | J38: =D$23-SUM(I$11:I38) -> 37648
C39: DEPOSIT - SALARY ADVANCE(REFUNDABLE) | D39: 1000 | G39: 29 | H39: =EDATE(H38,1) -> 46722 | I39: =$D$25 -> 4706 | J39: =D$23-SUM(I$11:I39) -> 32942
G40: 30 | H40: =EDATE(H39,1) -> 46753 | I40: =$D$25 -> 4706 | J40: =D$23-SUM(I$11:I40) -> 28236
G41: 31 | H41: =EDATE(H40,1) -> 46784 | I41: =$D$25 -> 4706 | J41: =D$23-SUM(I$11:I41) -> 23530
...

Sheet REPAYMENT-SCHEDULE
A1: STAR REGENCY LIMOUSINE TRANSPORTATION VIA LUXURY CARS
A2: AUTO LOAN REPAYMENT SCHEDULE
A3: Prepared in repayment-schedule format | Currency: AED
A5: Customer Name | B5: ='MAIN-LEXUS-FAISAL'!D5 -> MUHAMMAD FAISAL | D5: Vehicle Cost | E5: ='MAIN-LEXUS-FAISAL'!D17 -> 199000 | G5: Loan Tenure (Months) | H5: ='MAIN-LEXUS-FAISAL'!D24 -> 36
A6: Contact No. | B6: ='MAIN-LEXUS-FAISAL'!D6 -> +971 56 736 8995 | D6: Down Payment | E6: ='MAIN-LEXUS-FAISAL'!D19 -> 49750 | G6: Monthly Instalment | H6: ='MAIN-LEXUS-FAISAL'!D25 -> 4706
A7: Vehicle | B7: ='MAIN-LEXUS-FAISAL'!D10 -> LEXUS ES300H | D7: Finance Principal | E7: ='MAIN-LEXUS-FAISAL'!D20 -> 149250 | G7: Instalments Paid | H7: 12
A8: Chassis No. | B8: ='MAIN-LEXUS-FAISAL'!D11 -> JTHB21B16S2265896 | D8: Total Interest | E8: ='MAIN-LEXUS-FAISAL'!D22 -> 20166 | G8: Instalments Remaining | H8: =H5-H7 -> 24
A9: EMI Start Date | B9: ='MAIN-LEXUS-FAISAL'!D58 -> 45870 | D9: Total Contract Value | E9: ='MAIN-LEXUS-FAISAL'!D23 -> 169416 | G9: Paid to Date | H9: =SUMIF(A16:A51,"PAID",D16:D51) -> 56472
G10: Remaining Instalments | H10: =SUMIF(A16:A51,"PENDING",D16:D51) -> 112944
G11: Monthly Effective Rate | H11: =RATE(H5,-H6,E7) -> 0.0070175794
G12: Effective Annual Rate | H12: =(1+H11)^12-1 -> 0.087538461
A13: REPAYMENT SCHEDULE REPORT
A14: Status | B14: Instl No | C14: Due Date | D14: Installment Amt | E14: Principal Comp. | F14: Interest Comp. | G14: Opening Principal | H14: Closing Principal | I14: DAYS | J14: Adv Flag
A16: =IF(B16<=$H$7,"PAID","PENDING") -> PAID | B16: 1 | C16: ='MAIN-LEXUS-FAISAL'!H11 -> 45870 | D16: =E16+F16 -> 4706 | E16: =ROUND($H$6-F16,2) -> 3658.63 | F16: =ROUND(G16*$H$11,2) -> 1047.37 | G16: =$E$7 -> 149250 | H16: =ROUND(G16-E16,2) -> 145591.37 | I16: =31 -> 31
A17: =IF(B17<=$H$7,"PAID","PENDING") -> PAID | B17: 2 | C17: ='MAIN-LEXUS-FAISAL'!H12 -> 45901 | D17: =E17+F17 -> 4706 | E17: =ROUND($H$6-F17,2) -> 3684.3 | F17: =ROUND(G17*$H$11,2) -> 1021.7 | G17: =H16 -> 145591.37 | H17: =ROUND(G17-E17,2) -> 141907.07 | I17: =C17-C16 -> 31
A18: =IF(B18<=$H$7,"PAID","PENDING") -> PAID | B18: 3 | C18: ='MAIN-LEXUS-FAISAL'!H13 -> 45931 | D18: =E18+F18 -> 4706 | E18: =ROUND($H$6-F18,2) -> 3710.16 | F18: =ROUND(G18*$H$11,2) -> 995.84 | G18: =H17 -> 141907.07 | H18: =ROUND(G18-E18,2) -> 138196.91 | I18: =C18-C17 -> 30
A19: =IF(B19<=$H$7,"PAID","PENDING") -> PAID | B19: 4 | C19: ='MAIN-LEXUS-FAISAL'!H14 -> 45962 | D19: =E19+F19 -> 4706 | E19: =ROUND($H$6-F19,2) -> 3736.19 | F19: =ROUND(G19*$H$11,2) -> 969.81 | G19: =H18 -> 138196.91 | H19: =ROUND(G19-E19,2) -> 134460.72 | I19: =C19-C18 -> 31
A20: =IF(B20<=$H$7,"PAID","PENDING") -> PAID | B20: 5 | C20: ='MAIN-LEXUS-FAISAL'!H15 -> 45992 | D20: =E20+F20 -> 4706 | E20: =ROUND($H$6-F20,2) -> 3762.41 | F20: =ROUND(G20*$H$11,2) -> 943.59 | G20: =H19 -> 134460.72 | H20: =ROUND(G20-E20,2) -> 130698.31 | I20: =C20-C19 -> 30
A21: =IF(B21<=$H$7,"PAID","PENDING") -> PAID | B21: 6 | C21: ='MAIN-LEXUS-FAISAL'!H16 -> 46023 | D21: =E21+F21 -> 4706 | E21: =ROUND($H$6-F21,2) -> 3788.81 | F21: =ROUND(G21*$H$11,2) -> 917.19 | G21: =H20 -> 130698.31 | H21: =ROUND(G21-E21,2) -> 126909.5 | I21: =C21-C20 -> 31
A22: =IF(B22<=$H$7,"PAID","PENDING") -> PAID | B22: 7 | C22: ='MAIN-LEXUS-FAISAL'!H17 -> 46054 | D22: =E22+F22 -> 4706 | E22: =ROUND($H$6-F22,2) -> 3815.4 | F22: =ROUND(G22*$H$11,2) -> 890.6 | G22: =H21 -> 126909.5 | H22: =ROUND(G22-E22,2) -> 123094.1 | I22: =C22-C21 -> 31
A23: =IF(B23<=$H$7,"PAID","PENDING") -> PAID | B23: 8 | C23: ='MAIN-LEXUS-FAISAL'!H18 -> 46082 | D23: =E23+F23 -> 4706 | E23: =ROUND($H$6-F23,2) -> 3842.18 | F23: =ROUND(G23*$H$11,2) -> 863.82 | G23: =H22 -> 123094.1 | H23: =ROUND(G23-E23,2) -> 119251.92 | I23: =C23-C22 -> 28
A24: =IF(B24<=$H$7,"PAID","PENDING") -> PAID | B24: 9 | C24: ='MAIN-LEXUS-FAISAL'!H19 -> 46113 | D24: =E24+F24 -> 4706 | E24: =ROUND($H$6-F24,2) -> 3869.14 | F24: =ROUND(G24*$H$11,2) -> 836.86 | G24: =H23 -> 119251.92 | H24: =ROUND(G24-E24,2) -> 115382.78 | I24: =C24-C23 -> 31
A25: =IF(B25<=$H$7,"PAID","PENDING") -> PAID | B25: 10 | C25: ='MAIN-LEXUS-FAISAL'!H20 -> 46143 | D25: =E25+F25 -> 4706 | E25: =ROUND($H$6-F25,2) -> 3896.29 | F25: =ROUND(G25*$H$11,2) -> 809.71 | G25: =H24 -> 115382.78 | H25: =ROUND(G25-E25,2) -> 111486.49 | I25: =C25-C24 -> 30
A26: =IF(B26<=$H$7,"PAID","PENDING") -> PAID | B26: 11 | C26: ='MAIN-LEXUS-FAISAL'!H21 -> 46174 | D26: =E26+F26 -> 4706 | E26: =ROUND($H$6-F26,2) -> 3923.63 | F26: =ROUND(G26*$H$11,2) -> 782.37 | G26: =H25 -> 111486.49 | H26: =ROUND(G26-E26,2) -> 107562.86 | I26: =C26-C25 -> 31
A27: =IF(B27<=$H$7,"PAID","PENDING") -> PAID | B27: 12 | C27: ='MAIN-LEXUS-FAISAL'!H22 -> 46204 | D27: =E27+F27 -> 4706 | E27: =ROUND($H$6-F27,2) -> 3951.17 | F27: =ROUND(G27*$H$11,2) -> 754.83 | G27: =H26 -> 107562.86 | H27: =ROUND(G27-E27,2) -> 103611.69 | I27: =C27-C26 -> 30
A28: =IF(B28<=$H$7,"PAID","PENDING") -> PENDING | B28: 13 | C28: ='MAIN-LEXUS-FAISAL'!H23 -> 46235 | D28: =E28+F28 -> 4706 | E28: =ROUND($H$6-F28,2) -> 3978.9 | F28: =ROUND(G28*$H$11,2) -> 727.1 | G28: =H27 -> 103611.69 | H28: =ROUND(G28-E28,2) -> 99632.79 | I28: =C28-C27 -> 31
... A50: =IF(B50<=$H$7,"PAID","PENDING") -> PENDING | B50: 35 | C50: ='MAIN-LEXUS-FAISAL'!H45 -> 46905 | D50: =E50+F50 -> 4706 | E50: =ROUND($H$6-F50,2) -> 4640.64 | F50: =ROUND(G50*$H$11,2) -> 65.36 | G50: =H49 -> 9313.84 | H50: =ROUND(G50-E50,2) -> 4673.2 | I50: =C50-C49 -> 31
A51: =IF(B51<=$H$7,"PAID","PENDING") -> PENDING | B51: 36 | C51: ='MAIN-LEXUS-FAISAL'!H46 -> 46935 | D51: =E51+F51 -> 4706 | E51: =G51 -> 4673.2 | F51: =ROUND($E$8-SUM(F16:F50),2) -> 32.8 | G51: =H50 -> 4673.2 | H51: =ROUND(G51-E51,2) -> 0 | I51: =C51-C50 -> 30
A52: TOTAL / CLOSING | D52: =SUM(D16:D51) -> 169416 | E52: =SUM(E16:E51) -> 149250 | F52: =SUM(F16:F51) -> 20166 | G52: =G16 -> 149250 | H52: =H51 -> 0
A54: POSITION AFTER 12 PAID INSTALMENTS
A55: Paid instalments | C55: =$H$7 -> 12 | D55: Note: Outstanding principal is the amortized finance principal after 12 instalments; remaining contractual instalments include future interest.
A56: Total cash instalments paid | C56: =$H$9 -> 56472
A57: Outstanding principal | C57: =INDEX(H16:H51,$H$7) -> 103611.69
A58: Remaining contractual instalments | C58: =$H$10 -> 112944
